Exception on /ticket/ [GET]
Traceback (most recent call last):
  File "/usr/local/lib/python3.10/site-packages/flask/app.py", line 2073, in wsgi_app
    response = self.full_dispatch_request()
  File "/usr/local/lib/python3.10/site-packages/flask/app.py", line 1518, in full_dispatch_request
    rv = self.handle_user_exception(e)
  File "/usr/local/lib/python3.10/site-packages/flask/app.py", line 1516, in full_dispatch_request
    rv = self.dispatch_request()
  File "/usr/local/lib/python3.10/site-packages/flask/app.py", line 1502, in dispatch_request
    return self.ensure_sync(self.view_functions[rule.endpoint])(**req.view_args)
  File "/code/src/routes/utils/decorators.py", line 60, in secure_function
    return func(*args, **kwargs)
  File "/code/src/routes/Ticket.py", line 45, in tickets
    return render_template(
  File "/usr/local/lib/python3.10/site-packages/flask/templating.py", line 148, in render_template
    ctx.app.jinja_env.get_or_select_template(template_name_or_list),
  File "/usr/local/lib/python3.10/site-packages/jinja2/environment.py", line 1068, in get_or_select_template
    return self.get_template(template_name_or_list, parent, globals)
  File "/usr/local/lib/python3.10/site-packages/jinja2/environment.py", line 997, in get_template
    return self._load_template(name, globals)
  File "/usr/local/lib/python3.10/site-packages/jinja2/environment.py", line 958, in _load_template
    template = self.loader.load(self, name, self.make_globals(globals))
  File "/usr/local/lib/python3.10/site-packages/jinja2/loaders.py", line 137, in load
    code = environment.compile(source, name, filename)
  File "/usr/local/lib/python3.10/site-packages/jinja2/environment.py", line 757, in compile
    self.handle_exception(source=source_hint)
  File "/usr/local/lib/python3.10/site-packages/jinja2/environment.py", line 925, in handle_exception
    raise rewrite_traceback_stack(source=source)
  File "/code/src/templates/ticket.html", line 129, in <module>
    {% comment %} function new_ticket() {
jinja2.exceptions.TemplateSyntaxError: Encountered unknown tag 'comment'. Jinja was looking for the following tags: 'endblock'. The innermost block that needs to be closed is 'block'.
Exception on /ticket/ [GET]
Traceback (most recent call last):
  File "/usr/local/lib/python3.10/site-packages/flask/app.py", line 2073, in wsgi_app
    response = self.full_dispatch_request()
  File "/usr/local/lib/python3.10/site-packages/flask/app.py", line 1518, in full_dispatch_request
    rv = self.handle_user_exception(e)
  File "/usr/local/lib/python3.10/site-packages/flask/app.py", line 1516, in full_dispatch_request
    rv = self.dispatch_request()
  File "/usr/local/lib/python3.10/site-packages/flask/app.py", line 1502, in dispatch_request
    return self.ensure_sync(self.view_functions[rule.endpoint])(**req.view_args)
  File "/code/src/routes/utils/decorators.py", line 60, in secure_function
    return func(*args, **kwargs)
  File "/code/src/routes/Ticket.py", line 45, in tickets
    return render_template(
  File "/usr/local/lib/python3.10/site-packages/flask/templating.py", line 148, in render_template
    ctx.app.jinja_env.get_or_select_template(template_name_or_list),
  File "/usr/local/lib/python3.10/site-packages/jinja2/environment.py", line 1068, in get_or_select_template
    return self.get_template(template_name_or_list, parent, globals)
  File "/usr/local/lib/python3.10/site-packages/jinja2/environment.py", line 997, in get_template
    return self._load_template(name, globals)
  File "/usr/local/lib/python3.10/site-packages/jinja2/environment.py", line 958, in _load_template
    template = self.loader.load(self, name, self.make_globals(globals))
  File "/usr/local/lib/python3.10/site-packages/jinja2/loaders.py", line 137, in load
    code = environment.compile(source, name, filename)
  File "/usr/local/lib/python3.10/site-packages/jinja2/environment.py", line 757, in compile
    self.handle_exception(source=source_hint)
  File "/usr/local/lib/python3.10/site-packages/jinja2/environment.py", line 925, in handle_exception
    raise rewrite_traceback_stack(source=source)
  File "/code/src/templates/ticket.html", line 129, in <module>
    {% comment %} function new_ticket() {
jinja2.exceptions.TemplateSyntaxError: Encountered unknown tag 'comment'. Jinja was looking for the following tags: 'endblock'. The innermost block that needs to be closed is 'block'.
Exception on /ticket/ [GET]
Traceback (most recent call last):
  File "/usr/local/lib/python3.10/site-packages/flask/app.py", line 2073, in wsgi_app
    response = self.full_dispatch_request()
  File "/usr/local/lib/python3.10/site-packages/flask/app.py", line 1518, in full_dispatch_request
    rv = self.handle_user_exception(e)
  File "/usr/local/lib/python3.10/site-packages/flask/app.py", line 1516, in full_dispatch_request
    rv = self.dispatch_request()
  File "/usr/local/lib/python3.10/site-packages/flask/app.py", line 1502, in dispatch_request
    return self.ensure_sync(self.view_functions[rule.endpoint])(**req.view_args)
  File "/code/src/routes/utils/decorators.py", line 60, in secure_function
    return func(*args, **kwargs)
  File "/code/src/routes/Ticket.py", line 45, in tickets
    return render_template(
  File "/usr/local/lib/python3.10/site-packages/flask/templating.py", line 148, in render_template
    ctx.app.jinja_env.get_or_select_template(template_name_or_list),
  File "/usr/local/lib/python3.10/site-packages/jinja2/environment.py", line 1068, in get_or_select_template
    return self.get_template(template_name_or_list, parent, globals)
  File "/usr/local/lib/python3.10/site-packages/jinja2/environment.py", line 997, in get_template
    return self._load_template(name, globals)
  File "/usr/local/lib/python3.10/site-packages/jinja2/environment.py", line 958, in _load_template
    template = self.loader.load(self, name, self.make_globals(globals))
  File "/usr/local/lib/python3.10/site-packages/jinja2/loaders.py", line 137, in load
    code = environment.compile(source, name, filename)
  File "/usr/local/lib/python3.10/site-packages/jinja2/environment.py", line 757, in compile
    self.handle_exception(source=source_hint)
  File "/usr/local/lib/python3.10/site-packages/jinja2/environment.py", line 925, in handle_exception
    raise rewrite_traceback_stack(source=source)
  File "/code/src/templates/ticket.html", line 129, in <module>
    {% comment %} function new_ticket() {
jinja2.exceptions.TemplateSyntaxError: Encountered unknown tag 'comment'. Jinja was looking for the following tags: 'endblock'. The innermost block that needs to be closed is 'block'.
Exception on /ticket/ [GET]
Traceback (most recent call last):
  File "/usr/local/lib/python3.10/site-packages/flask/app.py", line 2073, in wsgi_app
    response = self.full_dispatch_request()
  File "/usr/local/lib/python3.10/site-packages/flask/app.py", line 1518, in full_dispatch_request
    rv = self.handle_user_exception(e)
  File "/usr/local/lib/python3.10/site-packages/flask/app.py", line 1516, in full_dispatch_request
    rv = self.dispatch_request()
  File "/usr/local/lib/python3.10/site-packages/flask/app.py", line 1502, in dispatch_request
    return self.ensure_sync(self.view_functions[rule.endpoint])(**req.view_args)
  File "/code/src/routes/utils/decorators.py", line 60, in secure_function
    return func(*args, **kwargs)
  File "/code/src/routes/Ticket.py", line 35, in tickets
    data = get_data()
TypeError: get_data() missing 1 required positional argument: 'path'
Exception on /ticket/ [GET]
Traceback (most recent call last):
  File "/usr/local/lib/python3.10/site-packages/flask/app.py", line 2073, in wsgi_app
    response = self.full_dispatch_request()
  File "/usr/local/lib/python3.10/site-packages/flask/app.py", line 1518, in full_dispatch_request
    rv = self.handle_user_exception(e)
  File "/usr/local/lib/python3.10/site-packages/flask/app.py", line 1516, in full_dispatch_request
    rv = self.dispatch_request()
  File "/usr/local/lib/python3.10/site-packages/flask/app.py", line 1502, in dispatch_request
    return self.ensure_sync(self.view_functions[rule.endpoint])(**req.view_args)
  File "/code/src/routes/utils/decorators.py", line 60, in secure_function
    return func(*args, **kwargs)
  File "/code/src/routes/Ticket.py", line 35, in tickets
    data = get_data()
TypeError: get_data() missing 1 required positional argument: 'path'
Exception on /ticket/add_to_car/1 [GET]
Traceback (most recent call last):
  File "/usr/local/lib/python3.10/site-packages/flask/app.py", line 2073, in wsgi_app
    response = self.full_dispatch_request()
  File "/usr/local/lib/python3.10/site-packages/flask/app.py", line 1518, in full_dispatch_request
    rv = self.handle_user_exception(e)
  File "/usr/local/lib/python3.10/site-packages/flask/app.py", line 1516, in full_dispatch_request
    rv = self.dispatch_request()
  File "/usr/local/lib/python3.10/site-packages/flask/app.py", line 1502, in dispatch_request
    return self.ensure_sync(self.view_functions[rule.endpoint])(**req.view_args)
  File "/code/src/routes/Ticket.py", line 94, in add_to_car
    session["payment"].append(data[idx])
TypeError: list indices must be integers or slices, not str
Exception on /ticket/ [GET]
Traceback (most recent call last):
  File "/usr/local/lib/python3.10/site-packages/flask/app.py", line 2073, in wsgi_app
    response = self.full_dispatch_request()
  File "/usr/local/lib/python3.10/site-packages/flask/app.py", line 1518, in full_dispatch_request
    rv = self.handle_user_exception(e)
  File "/usr/local/lib/python3.10/site-packages/flask/app.py", line 1516, in full_dispatch_request
    rv = self.dispatch_request()
  File "/usr/local/lib/python3.10/site-packages/flask/app.py", line 1502, in dispatch_request
    return self.ensure_sync(self.view_functions[rule.endpoint])(**req.view_args)
  File "/code/src/routes/utils/decorators.py", line 60, in secure_function
    return func(*args, **kwargs)
  File "/code/src/routes/Ticket.py", line 36, in tickets
    idx = int(idx)
TypeError: int() argument must be a string, a bytes-like object or a real number, not 'NoneType'
Exception on /ticket/ [GET]
Traceback (most recent call last):
  File "/usr/local/lib/python3.10/site-packages/flask/app.py", line 2073, in wsgi_app
    response = self.full_dispatch_request()
  File "/usr/local/lib/python3.10/site-packages/flask/app.py", line 1518, in full_dispatch_request
    rv = self.handle_user_exception(e)
  File "/usr/local/lib/python3.10/site-packages/flask/app.py", line 1516, in full_dispatch_request
    rv = self.dispatch_request()
  File "/usr/local/lib/python3.10/site-packages/flask/app.py", line 1502, in dispatch_request
    return self.ensure_sync(self.view_functions[rule.endpoint])(**req.view_args)
  File "/code/src/routes/utils/decorators.py", line 60, in secure_function
    return func(*args, **kwargs)
  File "/code/src/routes/Ticket.py", line 36, in tickets
    idx = int(idx)
TypeError: int() argument must be a string, a bytes-like object or a real number, not 'NoneType'
Exception on /ticket/add_to_car/1 [GET]
Traceback (most recent call last):
  File "/usr/local/lib/python3.10/site-packages/flask/app.py", line 2073, in wsgi_app
    response = self.full_dispatch_request()
  File "/usr/local/lib/python3.10/site-packages/flask/app.py", line 1519, in full_dispatch_request
    return self.finalize_request(rv)
  File "/usr/local/lib/python3.10/site-packages/flask/app.py", line 1538, in finalize_request
    response = self.make_response(rv)
  File "/usr/local/lib/python3.10/site-packages/flask/app.py", line 1701, in make_response
    raise TypeError(
TypeError: The view function for 'Ticket.add_to_car' did not return a valid response. The function either returned None or ended without a return statement.
Exception on /ticket/add_to_car/1 [GET]
Traceback (most recent call last):
  File "/usr/local/lib/python3.10/site-packages/flask/app.py", line 2073, in wsgi_app
    response = self.full_dispatch_request()
  File "/usr/local/lib/python3.10/site-packages/flask/app.py", line 1519, in full_dispatch_request
    return self.finalize_request(rv)
  File "/usr/local/lib/python3.10/site-packages/flask/app.py", line 1538, in finalize_request
    response = self.make_response(rv)
  File "/usr/local/lib/python3.10/site-packages/flask/app.py", line 1701, in make_response
    raise TypeError(
TypeError: The view function for 'Ticket.add_to_car' did not return a valid response. The function either returned None or ended without a return statement.
Exception on /ticket/drop_ticket [GET]
Traceback (most recent call last):
  File "/usr/local/lib/python3.10/site-packages/flask/app.py", line 2073, in wsgi_app
    response = self.full_dispatch_request()
  File "/usr/local/lib/python3.10/site-packages/flask/app.py", line 1518, in full_dispatch_request
    rv = self.handle_user_exception(e)
  File "/usr/local/lib/python3.10/site-packages/flask/app.py", line 1516, in full_dispatch_request
    rv = self.dispatch_request()
  File "/usr/local/lib/python3.10/site-packages/flask/app.py", line 1502, in dispatch_request
    return self.ensure_sync(self.view_functions[rule.endpoint])(**req.view_args)
  File "/code/src/routes/Ticket.py", line 126, in drop_ticket
    idx = int(request.args.get("drop_idx"))
TypeError: int() argument must be a string, a bytes-like object or a real number, not 'NoneType'
Exception on /ticket/add_to_car/1 [GET]
Traceback (most recent call last):
  File "/usr/local/lib/python3.10/site-packages/flask/app.py", line 2073, in wsgi_app
    response = self.full_dispatch_request()
  File "/usr/local/lib/python3.10/site-packages/flask/app.py", line 1519, in full_dispatch_request
    return self.finalize_request(rv)
  File "/usr/local/lib/python3.10/site-packages/flask/app.py", line 1538, in finalize_request
    response = self.make_response(rv)
  File "/usr/local/lib/python3.10/site-packages/flask/app.py", line 1701, in make_response
    raise TypeError(
TypeError: The view function for 'Ticket.add_to_car' did not return a valid response. The function either returned None or ended without a return statement.
Exception on /ticket/add_to_car/1 [GET]
Traceback (most recent call last):
  File "/usr/local/lib/python3.10/site-packages/flask/app.py", line 2073, in wsgi_app
    response = self.full_dispatch_request()
  File "/usr/local/lib/python3.10/site-packages/flask/app.py", line 1519, in full_dispatch_request
    return self.finalize_request(rv)
  File "/usr/local/lib/python3.10/site-packages/flask/app.py", line 1538, in finalize_request
    response = self.make_response(rv)
  File "/usr/local/lib/python3.10/site-packages/flask/app.py", line 1701, in make_response
    raise TypeError(
TypeError: The view function for 'Ticket.add_to_car' did not return a valid response. The function either returned None or ended without a return statement.
Exception on /ticket/add_to_car/1 [GET]
Traceback (most recent call last):
  File "/usr/local/lib/python3.10/site-packages/flask/app.py", line 2073, in wsgi_app
    response = self.full_dispatch_request()
  File "/usr/local/lib/python3.10/site-packages/flask/app.py", line 1519, in full_dispatch_request
    return self.finalize_request(rv)
  File "/usr/local/lib/python3.10/site-packages/flask/app.py", line 1538, in finalize_request
    response = self.make_response(rv)
  File "/usr/local/lib/python3.10/site-packages/flask/app.py", line 1701, in make_response
    raise TypeError(
TypeError: The view function for 'Ticket.add_to_car' did not return a valid response. The function either returned None or ended without a return statement.
Exception on /ticket/add_to_car/1 [GET]
Traceback (most recent call last):
  File "/usr/local/lib/python3.10/site-packages/flask/app.py", line 2073, in wsgi_app
    response = self.full_dispatch_request()
  File "/usr/local/lib/python3.10/site-packages/flask/app.py", line 1519, in full_dispatch_request
    return self.finalize_request(rv)
  File "/usr/local/lib/python3.10/site-packages/flask/app.py", line 1538, in finalize_request
    response = self.make_response(rv)
  File "/usr/local/lib/python3.10/site-packages/flask/app.py", line 1701, in make_response
    raise TypeError(
TypeError: The view function for 'Ticket.add_to_car' did not return a valid response. The function either returned None or ended without a return statement.
Exception on /ticket/add_to_car/1 [GET]
Traceback (most recent call last):
  File "/usr/local/lib/python3.10/site-packages/flask/app.py", line 2073, in wsgi_app
    response = self.full_dispatch_request()
  File "/usr/local/lib/python3.10/site-packages/flask/app.py", line 1519, in full_dispatch_request
    return self.finalize_request(rv)
  File "/usr/local/lib/python3.10/site-packages/flask/app.py", line 1538, in finalize_request
    response = self.make_response(rv)
  File "/usr/local/lib/python3.10/site-packages/flask/app.py", line 1701, in make_response
    raise TypeError(
TypeError: The view function for 'Ticket.add_to_car' did not return a valid response. The function either returned None or ended without a return statement.
Exception on /ticket/drop_ticket [GET]
Traceback (most recent call last):
  File "/usr/local/lib/python3.10/site-packages/flask/app.py", line 2073, in wsgi_app
    response = self.full_dispatch_request()
  File "/usr/local/lib/python3.10/site-packages/flask/app.py", line 1518, in full_dispatch_request
    rv = self.handle_user_exception(e)
  File "/usr/local/lib/python3.10/site-packages/flask/app.py", line 1516, in full_dispatch_request
    rv = self.dispatch_request()
  File "/usr/local/lib/python3.10/site-packages/flask/app.py", line 1502, in dispatch_request
    return self.ensure_sync(self.view_functions[rule.endpoint])(**req.view_args)
  File "/code/src/routes/Ticket.py", line 126, in drop_ticket
TypeError: int() argument must be a string, a bytes-like object or a real number, not 'NoneType'
Exception on /ticket/add_to_car/1 [GET]
Traceback (most recent call last):
  File "/usr/local/lib/python3.10/site-packages/flask/app.py", line 2073, in wsgi_app
    response = self.full_dispatch_request()
  File "/usr/local/lib/python3.10/site-packages/flask/app.py", line 1518, in full_dispatch_request
    rv = self.handle_user_exception(e)
  File "/usr/local/lib/python3.10/site-packages/flask/app.py", line 1516, in full_dispatch_request
    rv = self.dispatch_request()
  File "/usr/local/lib/python3.10/site-packages/flask/app.py", line 1502, in dispatch_request
    return self.ensure_sync(self.view_functions[rule.endpoint])(**req.view_args)
  File "/code/src/routes/Ticket.py", line 98, in add_to_car
    return redirect(url_for('tickets'))
  File "/usr/local/lib/python3.10/site-packages/flask/helpers.py", line 338, in url_for
    return appctx.app.handle_url_build_error(error, endpoint, values)
  File "/usr/local/lib/python3.10/site-packages/flask/helpers.py", line 325, in url_for
    rv = url_adapter.build(
  File "/usr/local/lib/python3.10/site-packages/werkzeug/routing.py", line 2314, in build
    raise BuildError(endpoint, values, method, self)
werkzeug.routing.BuildError: Could not build url for endpoint 'tickets'. Did you mean 'Ticket.pays' instead?
Exception on /ticket/add_to_car/1 [GET]
Traceback (most recent call last):
  File "/usr/local/lib/python3.10/site-packages/flask/app.py", line 2073, in wsgi_app
    response = self.full_dispatch_request()
  File "/usr/local/lib/python3.10/site-packages/flask/app.py", line 1518, in full_dispatch_request
    rv = self.handle_user_exception(e)
  File "/usr/local/lib/python3.10/site-packages/flask/app.py", line 1516, in full_dispatch_request
    rv = self.dispatch_request()
  File "/usr/local/lib/python3.10/site-packages/flask/app.py", line 1502, in dispatch_request
    return self.ensure_sync(self.view_functions[rule.endpoint])(**req.view_args)
  File "/code/src/routes/Ticket.py", line 98, in add_to_car
    return redirect(url_for('tickets'))
  File "/usr/local/lib/python3.10/site-packages/flask/helpers.py", line 338, in url_for
    return appctx.app.handle_url_build_error(error, endpoint, values)
  File "/usr/local/lib/python3.10/site-packages/flask/helpers.py", line 325, in url_for
    rv = url_adapter.build(
  File "/usr/local/lib/python3.10/site-packages/werkzeug/routing.py", line 2314, in build
    raise BuildError(endpoint, values, method, self)
werkzeug.routing.BuildError: Could not build url for endpoint 'tickets'. Did you mean 'Ticket.pays' instead?
Exception on /ticket/add_to_car/1 [GET]
Traceback (most recent call last):
  File "/usr/local/lib/python3.10/site-packages/flask/app.py", line 2073, in wsgi_app
    response = self.full_dispatch_request()
  File "/usr/local/lib/python3.10/site-packages/flask/app.py", line 1518, in full_dispatch_request
    rv = self.handle_user_exception(e)
  File "/usr/local/lib/python3.10/site-packages/flask/app.py", line 1516, in full_dispatch_request
    rv = self.dispatch_request()
  File "/usr/local/lib/python3.10/site-packages/flask/app.py", line 1502, in dispatch_request
    return self.ensure_sync(self.view_functions[rule.endpoint])(**req.view_args)
  File "/code/src/routes/Ticket.py", line 98, in add_to_car
    return redirect(url_for('tickets'))
  File "/usr/local/lib/python3.10/site-packages/flask/helpers.py", line 338, in url_for
    return appctx.app.handle_url_build_error(error, endpoint, values)
  File "/usr/local/lib/python3.10/site-packages/flask/helpers.py", line 325, in url_for
    rv = url_adapter.build(
  File "/usr/local/lib/python3.10/site-packages/werkzeug/routing.py", line 2314, in build
    raise BuildError(endpoint, values, method, self)
werkzeug.routing.BuildError: Could not build url for endpoint 'tickets'. Did you mean 'Ticket.pays' instead?
Exception on /ticket/add_to_car/1 [GET]
Traceback (most recent call last):
  File "/usr/local/lib/python3.10/site-packages/flask/app.py", line 2073, in wsgi_app
    response = self.full_dispatch_request()
  File "/usr/local/lib/python3.10/site-packages/flask/app.py", line 1518, in full_dispatch_request
    rv = self.handle_user_exception(e)
  File "/usr/local/lib/python3.10/site-packages/flask/app.py", line 1516, in full_dispatch_request
    rv = self.dispatch_request()
  File "/usr/local/lib/python3.10/site-packages/flask/app.py", line 1502, in dispatch_request
    return self.ensure_sync(self.view_functions[rule.endpoint])(**req.view_args)
  File "/code/src/routes/Ticket.py", line 98, in add_to_car
    return redirect(url_for('tickets'))
  File "/usr/local/lib/python3.10/site-packages/flask/helpers.py", line 338, in url_for
    return appctx.app.handle_url_build_error(error, endpoint, values)
  File "/usr/local/lib/python3.10/site-packages/flask/helpers.py", line 325, in url_for
    rv = url_adapter.build(
  File "/usr/local/lib/python3.10/site-packages/werkzeug/routing.py", line 2314, in build
    raise BuildError(endpoint, values, method, self)
werkzeug.routing.BuildError: Could not build url for endpoint 'tickets'. Did you mean 'Ticket.pays' instead?
Exception on /ticket/add_to_car/1 [GET]
Traceback (most recent call last):
  File "/usr/local/lib/python3.10/site-packages/flask/app.py", line 2073, in wsgi_app
    response = self.full_dispatch_request()
  File "/usr/local/lib/python3.10/site-packages/flask/app.py", line 1518, in full_dispatch_request
    rv = self.handle_user_exception(e)
  File "/usr/local/lib/python3.10/site-packages/flask/app.py", line 1516, in full_dispatch_request
    rv = self.dispatch_request()
  File "/usr/local/lib/python3.10/site-packages/flask/app.py", line 1502, in dispatch_request
    return self.ensure_sync(self.view_functions[rule.endpoint])(**req.view_args)
  File "/code/src/routes/Ticket.py", line 98, in add_to_car
    return redirect(url_for('tickets'))
  File "/usr/local/lib/python3.10/site-packages/flask/helpers.py", line 338, in url_for
    return appctx.app.handle_url_build_error(error, endpoint, values)
  File "/usr/local/lib/python3.10/site-packages/flask/helpers.py", line 325, in url_for
    rv = url_adapter.build(
  File "/usr/local/lib/python3.10/site-packages/werkzeug/routing.py", line 2314, in build
    raise BuildError(endpoint, values, method, self)
werkzeug.routing.BuildError: Could not build url for endpoint 'tickets'. Did you mean 'Ticket.pays' instead?
Exception on /ticket/drop_from_car [GET]
Traceback (most recent call last):
  File "/usr/local/lib/python3.10/site-packages/flask/app.py", line 2073, in wsgi_app
    response = self.full_dispatch_request()
  File "/usr/local/lib/python3.10/site-packages/flask/app.py", line 1518, in full_dispatch_request
    rv = self.handle_user_exception(e)
  File "/usr/local/lib/python3.10/site-packages/flask/app.py", line 1516, in full_dispatch_request
    rv = self.dispatch_request()
  File "/usr/local/lib/python3.10/site-packages/flask/app.py", line 1502, in dispatch_request
    return self.ensure_sync(self.view_functions[rule.endpoint])(**req.view_args)
  File "/code/src/routes/Ticket.py", line 111, in drop_from_car
    return redirect(url_for('tickets'))
  File "/usr/local/lib/python3.10/site-packages/flask/helpers.py", line 338, in url_for
    return appctx.app.handle_url_build_error(error, endpoint, values)
  File "/usr/local/lib/python3.10/site-packages/flask/helpers.py", line 325, in url_for
    rv = url_adapter.build(
  File "/usr/local/lib/python3.10/site-packages/werkzeug/routing.py", line 2314, in build
    raise BuildError(endpoint, values, method, self)
werkzeug.routing.BuildError: Could not build url for endpoint 'tickets'. Did you mean 'Ticket.pays' instead?
Exception on /ticket/add_to_car/1 [GET]
Traceback (most recent call last):
  File "/usr/local/lib/python3.10/site-packages/flask/app.py", line 2073, in wsgi_app
    response = self.full_dispatch_request()
  File "/usr/local/lib/python3.10/site-packages/flask/app.py", line 1518, in full_dispatch_request
    rv = self.handle_user_exception(e)
  File "/usr/local/lib/python3.10/site-packages/flask/app.py", line 1516, in full_dispatch_request
    rv = self.dispatch_request()
  File "/usr/local/lib/python3.10/site-packages/flask/app.py", line 1502, in dispatch_request
    return self.ensure_sync(self.view_functions[rule.endpoint])(**req.view_args)
  File "/code/src/routes/Ticket.py", line 98, in add_to_car
    return redirect(url_for('tickets'))
  File "/usr/local/lib/python3.10/site-packages/flask/helpers.py", line 338, in url_for
    return appctx.app.handle_url_build_error(error, endpoint, values)
  File "/usr/local/lib/python3.10/site-packages/flask/helpers.py", line 325, in url_for
    rv = url_adapter.build(
  File "/usr/local/lib/python3.10/site-packages/werkzeug/routing.py", line 2314, in build
    raise BuildError(endpoint, values, method, self)
werkzeug.routing.BuildError: Could not build url for endpoint 'tickets'. Did you mean 'Ticket.pays' instead?
Exception on /ticket/add_to_car/1 [GET]
Traceback (most recent call last):
  File "/usr/local/lib/python3.10/site-packages/flask/app.py", line 2073, in wsgi_app
    response = self.full_dispatch_request()
  File "/usr/local/lib/python3.10/site-packages/flask/app.py", line 1518, in full_dispatch_request
    rv = self.handle_user_exception(e)
  File "/usr/local/lib/python3.10/site-packages/flask/app.py", line 1516, in full_dispatch_request
    rv = self.dispatch_request()
  File "/usr/local/lib/python3.10/site-packages/flask/app.py", line 1502, in dispatch_request
    return self.ensure_sync(self.view_functions[rule.endpoint])(**req.view_args)
  File "/code/src/routes/Ticket.py", line 98, in add_to_car
    return redirect(url_for('tickets'))
  File "/usr/local/lib/python3.10/site-packages/flask/helpers.py", line 338, in url_for
    return appctx.app.handle_url_build_error(error, endpoint, values)
  File "/usr/local/lib/python3.10/site-packages/flask/helpers.py", line 325, in url_for
    rv = url_adapter.build(
  File "/usr/local/lib/python3.10/site-packages/werkzeug/routing.py", line 2314, in build
    raise BuildError(endpoint, values, method, self)
werkzeug.routing.BuildError: Could not build url for endpoint 'tickets'. Did you mean 'Ticket.pays' instead?
Exception on /ticket/add_to_car/1 [GET]
Traceback (most recent call last):
  File "/usr/local/lib/python3.10/site-packages/flask/app.py", line 2073, in wsgi_app
    response = self.full_dispatch_request()
  File "/usr/local/lib/python3.10/site-packages/flask/app.py", line 1518, in full_dispatch_request
    rv = self.handle_user_exception(e)
  File "/usr/local/lib/python3.10/site-packages/flask/app.py", line 1516, in full_dispatch_request
    rv = self.dispatch_request()
  File "/usr/local/lib/python3.10/site-packages/flask/app.py", line 1502, in dispatch_request
    return self.ensure_sync(self.view_functions[rule.endpoint])(**req.view_args)
  File "/code/src/routes/Ticket.py", line 98, in add_to_car
    return redirect(url_for('tickets'))
  File "/usr/local/lib/python3.10/site-packages/flask/helpers.py", line 338, in url_for
    return appctx.app.handle_url_build_error(error, endpoint, values)
  File "/usr/local/lib/python3.10/site-packages/flask/helpers.py", line 325, in url_for
    rv = url_adapter.build(
  File "/usr/local/lib/python3.10/site-packages/werkzeug/routing.py", line 2314, in build
    raise BuildError(endpoint, values, method, self)
werkzeug.routing.BuildError: Could not build url for endpoint 'tickets'. Did you mean 'Ticket.pays' instead?
